Workbook
Name Beam: Lists!$B$2:$B$25
Name BeamP: Lists!$B$49:$B$82
Name Class: #REF!
Name Class: #REF!
Name Class: #REF!
Name Class: #REF!
Name Column: Lists!$C$2:$C$29
Name ColumnP: Lists!$C$50:$C$86
Name CondOp: #REF!
Name CondOp: #REF!
Name CondOp: #REF!
Name CondOp: #REF!
Name Door: Lists!$D$2:$D$38
Name DoorP: Lists!$D$49:$D$92
Name element: #REF!
Name element: #REF!
Name Iscon: #REF!
Name Iscon: #REF!
Name Iscon: #REF!
Name Iscon: #REF!
Name MEP: Lists!$F$2:$F$12
Name MEPP: Lists!$F$49:$F$66
Name Mesh: Lists!$E$2:$E$16
Name MeshP: Lists!$E$49:$E$69
Name Object: Lists!$G$2:$G$9
Name ObjectP: Lists!$G$49:$G$63
Name Operator: #REF!
Name Operator: #REF!
Name Operator: #REF!
Name Operator: Lists!$A$1:$A$7
Name PROC: #REF!
Name PROC: #REF!
Name q2ty: #REF!
Name q2ty: #REF!
Name q2ty: #REF!
Name q2ty: #REF!
Name qty: #REF!
Name qty: #REF!
Name qty: #REF!
Name QTY: #REF!
Name QTYTYPES: Quantities!$A$2:$A$178
Name Roof: Lists!$H$2:$H$18
Name RoofP: Lists!$H$47:$H$71
Name Slab: Lists!$I$2:$I$30
Name SlabP: Lists!$I$54:$I$90
Name Stair: Lists!$J$2:$J$22
Name StairP: Lists!$J$49:$J$75
Name Wall: Lists!$K$2:$K$40
Name WallP: Lists!$K$43:$K$89
Name Window: Lists!$L$2:$L$38
Name WindowP: Lists!$L$50:$L$92
Name Zone: Lists!$M$2:$M$35
Name ZoneP: Lists!$M$56:$M$99

Sheet GraphML_WBS
A1: Code, 1 | B1: Code, 2 | C1: Code, 3 | D1: Code, 4 | E1: Code, 5 | F1: Code, 6 | G1: RSMEANS | H1: RS Unit | I1: RS <> WBS Unit conv. | J1: RS HR cons. | K1: RS $ cons. | L1: Description | M1: Unit | N1: Units | O1: Consumption | P1: Waste Factor | Q1: Unit Cost | R1: Source Qty | T1: Tag-Uniformat 1 | U1: Tag-Uniformat 2 | V1: Tag-Uniformat 3 | W1: Tag-Uniformat 4 | X1: Tag-CSI 1 | Y1: Tag-CSI 2 | Z1: Tag-Cost Type | AA1: Tag-Labor Resource | AB1: Tag-CSI Resource 1 | AC1: Tag-CSI Resource 2 | AE1: Node
A2: G | L2: BUILDING SITEWORK | M2: - | N2: - | O2: 1 | P2: 1 | Q2: 0 | R2: 1 | T2: G - BUILDING SITEWORK | AE2: 1
B3: G10 | L3: Site Preparation | M3: - | N3: - | O3: 1 | P3: 1 | Q3: 0 | R3: 1 | T3: G - BUILDING SITEWORK | U3: G10 - Site Preparation | AE3: 2
D4: G1031.001 | L4: Cut and Fill | M4: CY | N4: CY/CY | O4: 1 | P4: 1 | Q4: 0 | R4: G1031.001_Cut and Fill.Net Volume | T4: G - BUILDING SITEWORK | U4: G10 - Site Preparation | V4: G1030 - Site Earthwork | W4: G1031 - Site Grading Excavation | AE4: 4
E5: 31.23.00.100.0 | G5: 31 23 16.46 2420 | H5: B.C.Y | I5: 1 | J5: 0.12 | K5: 15.8 | L5: Mass Excavation to Reduce levels | M5: CY | N5: CY/CY | O5: 1 | P5: 1 | Q5: 0 | R5: G1031.001_Cut and Fill.Net Volume | T5: G - BUILDING SITEWORK | U5: G10 - Site Preparation | V5: G1030 - Site Earthwork | W5: G1031 - Site Grading Excavation | X5: 31 - EARTHWORK | Y5: 31 23 00 - Excavation and Fill | AE5: 5
F6: LEXC001 | L6: Excavation Labor | M6: HR | N6: HR/CY | O6: 0.096 | P6: 1 | Q6: 0 | R6: Parent.Quantity | T6: G - BUILDING SITEWORK | U6: G10 - Site Preparation | V6: G1030 - Site Earthwork | W6: G1031 - Site Grading Excavation | X6: 31 - EARTHWORK | Y6: 31 23 00 - Excavation and Fill | Z6: Labor | AA6: LEXC | AE6: 6
F7: PEXC0103 | L7: Excavator | M7: HR | N7: HR/CY | O7: 0.096 | P7: 1 | Q7: 0 | R7: Parent.Quantity | T7: G - BUILDING SITEWORK | U7: G10 - Site Preparation | V7: G1030 - Site Earthwork | W7: G1031 - Site Grading Excavation | X7: 31 - EARTHWORK | Y7: 31 23 00 - Excavation and Fill | Z7: Machinery | AE7: 6
E8: 31.23.20.100.0 | G8: 30 23 23.14 2020 | H8: L.C.Y. | I8: 1.25 | J8: 0.012 | K8: 1.62 | L8: Mass Fill to Make up levels | M8: CY | N8: CY/CY | O8: 1 | P8: 1 | Q8: 0 | R8: G1031.001_Cut and Fill.Net Volume | T8: G - BUILDING SITEWORK | U8: G10 - Site Preparation | V8: G1030 - Site Earthwork | W8: G1031 - Site Grading Excavation | X8: 31 - EARTHWORK | Y8: 31 23 20 - Excavation and Fill | AE8: 5
F9: LEXC001 | L9: Excavation Labor | M9: HR | N9: HR/CY | O9: 0.026 | P9: 1 | Q9: 0 | R9: Parent.Quantity | T9: G - BUILDING SITEWORK | U9: G10 - Site Preparation | V9: G1030 - Site Earthwork | W9: G1031 - Site Grading Excavation | X9: 31 - EARTHWORK | Y9: 31 23 20 - Excavation and Fill | Z9: Labor | AA9: LEXC | AE9: 6
F10: PEXC0103 | L10: Excavator | M10: HR | N10: HR/CY | O10: 0.026 | P10: 1 | Q10: 0 | R10: Parent.Quantity | T10: G - BUILDING SITEWORK | U10: G10 - Site Preparation | V10: G1030 - Site Earthwork | W10: G1031 - Site Grading Excavation | X10: 31 - EARTHWORK | Y10: 31 23 20 - Excavation and Fill | Z10: Machinery | AE10: 6
F11: M31.23.20.100 | L11: Imported Fill Material | M11: HR | N11: HR/CY | O11: 0.026 | P11: 1 | Q11: 0 | R11: Parent.Quantity | T11: G - BUILDING SITEWORK | U11: G10 - Site Preparation | V11: G1030 - Site Earthwork | W11: G1031 - Site Grading Excavation | X11: 31 - EARTHWORK | Y11: 31 23 20 - Excavation and Fill | Z11: Material | AB11: M31 | AC11: M31 23 20 | AE11: 6
E12: 31.23.20.100.0 | G12: 33 23 23.24 0600 | H12: E.C.Y. | I12: 0.9 | J12: 0.04 | K12: 3.34 | L12: Fill compaction - Vibratory plate | M12: CY | N12: CY/CY | O12: 1 | P12: 1 | Q12: 0 | R12: G1031.001_Cut and Fill.Net Volume | T12: G - BUILDING SITEWORK | U12: G10 - Site Preparation | V12: G1030 - Site Earthwork | W12: G1031 - Site Grading Excavation | X12: 31 - EARTHWORK | Y12: 31 23 20 - Excavation and Fill | AE12: 5
F13: LEXC001 | L13: Excavation Labor | M13: HR | N13: HR/CY | O13: 0.026 | P13: 1 | Q13: 0 | R13: Parent.Quantity | T13: G - BUILDING SITEWORK | U13: G10 - Site Preparation | V13: G1030 - Site Earthwork | W13: G1031 - Site Grading Excavation | X13: 31 - EARTHWORK | Y13: 31 23 20 - Excavation and Fill | Z13: Labor | AA13: LEXC | AE13: 6
E14: 31.23.30.100.0 | G14: 31 23 23.20 0014 | H14: L.C.Y. | I14: 1.25 | J14: 0.03 | K14: 3.33 | L14: Remove Surplus Excavated Material | M14: CY | N14: CY/CY | O14: 1 | P14: 1 | Q14: 0 | R14: G1031.001_Cut and Fill.Net Volume | T14: G - BUILDING SITEWORK | U14: G10 - Site Preparation | V14: G1030 - Site Earthwork | W14: G1031 - Site Grading Excavation | X14: 31 - EARTHWORK | Y14: 31 23 30 - Excavation and Fill | AE14: 5
F15: LEXC001 | L15: Excavation Labor | M15: HR | N15: HR/CY | O15: 0.07 | P15: 1 | Q15: 0 | R15: Parent.Quantity | T15: G - BUILDING SITEWORK | U15: G10 - Site Preparation | V15: G1030 - Site Earthwork | W15: G1031 - Site Grading Excavation | X15: 31 - EARTHWORK | Y15: 31 23 30 - Excavation and Fill | Z15: Labor | AA15: LEXC | AE15: 6
F16: PDIS0101 | L16: Haul Spoils off Site | M16: CY | N16: CY/CY | O16: 1 | P16: 1 | Q16: 0 | R16: Parent.Quantity | T16: G - BUILDING SITEWORK | U16: G10 - Site Preparation | V16: G1030 - Site Earthwork | W16: G1031 - Site Grading Excavation | X16: 31 - EARTHWORK | Y16: 31 23 30 - Excavation and Fill | Z16: Machinery | AE16: 6
A17: A | L17: SUBSTRUCTURE | M17: - | O17: 1 | P17: 1 | Q17: 0 | R17: 1 | T17: A - SUBSTRUCTURE | AE17: 1
B18: A10 | L18: Foundations | M18: - | O18: 1 | P18: 1 | Q18: 0 | R18: 1 | T18: A - SUBSTRUCTURE | U18: A10 - Foundations | AE18: 2
C19: A1010 | L19: Standard | M19: - | O19: 1 | P19: 1 | Q19: 0 | R19: 1 | T19: A - SUBSTRUCTURE | U19: A10 - Foundations | V19: A1010 - Standard | AE19: 3
D20: A1012_001 | L20: CIP Pad Footing-ID | M20: CY | O20: 1 | P20: 1 | Q20: 0 | R20: A1012_001_CIP Pad Footing-ID.Net Volume | T20: A - SUBSTRUCTURE | U20: A10 - Foundations | V20: A1010 - Standard | W20: A1012 - Column Foundations & Pile Caps | AE20: 4 | AF20: A1012_001
E21: 31.23.00.010.0 | G21: 31 23 16.15 6030 | H21: B.C.Y | I21: 1 | J21: 0.29 | K21: 15.85 | L21: Excavate Pad Footings | M21: CY | N21: CY/CY | O21: 1 | P21: 1 | Q21: 0 | R21: A1012_001_CIP Pad Footing-ID.Net Volume | T21: A - SUBSTRUCTURE | U21: A10 - Foundations | V21: A1010 - Standard | W21: A1012 - Column Foundations & Pile Caps | X21: 31 - EARTHWORK | Y21: 31 23 00 - Excavation and Fill | AE21: 5
F22: LEXC001 | G22: 32 23 16.15 6030 | J22: 0.291 | K22: 15.85 | L22: Excavation Labor | M22: HR | N22: HR/CY | O22: 0.2 | P22: 1 | Q22: 0 | R22: Parent.Quantity | T22: A - SUBSTRUCTURE | U22: A10 - Foundations | V22: A1010 - Standard | W22: A1012 - Column Foundations & Pile Caps | X22: 31 - EARTHWORK | Y22: 31 23 00 - Excavation and Fill | Z22: Labor | AA22: LEXC | AE22: 6
F23: PEXC0101 | L23: JCB 3C | M23: HR | N23: HR/CY | O23: 0.4 | P23: 1 | Q23: 0 | R23: Parent.Quantity | T23: A - SUBSTRUCTURE | U23: A10 - Foundations | V23: A1010 - Standard | W23: A1012 - Column Foundations & Pile Caps | X23: 31 - EARTHWORK | Y23: 31 23 00 - Excavation and Fill | Z23: Machinery | AE23: 6
E24: 31.23.00.040.0 | G24: 31 23 16.15 6030 | H24: B.C.Y | I24: 1 | J24: 0.29 | K24: 15.85 | L24: Excavate layback for excavation | M24: CY | N24: CY/CY | O24: 1 | P24: 1 | Q24: 0 | R24: A1012_001_CIP Pad Footing-ID.Edge Surface Area | T24: A - SUBSTRUCTURE | U24: A10 - Foundations | V24: A1010 - Standard | W24: A1012 - Column Foundations & Pile Caps | X24: 31 - EARTHWORK | Y24: 31 23 00 - Excavation and Fill | AE24: 5
F25: LEXC001 | G25: 32 23 16.15 6030 | J25: 0.291 | K25: 15.85 | L25: Excavation Labor | M25: HR | N25: HR/CY | O25: 0.2 | P25: 1 | Q25: 0 | R25: Parent.Quantity | T25: A - SUBSTRUCTURE | U25: A10 - Foundations | V25: A1010 - Standard | W25: A1012 - Column Foundations & Pile Caps | X25: 31 - EARTHWORK | Y25: 31 23 00 - Excavation and Fill | Z25: Labor | AA25: LEXC | AE25: 6
F26: PEXC0101 | L26: JCB 3C | M26: HR | N26: HR/CY | O26: 0.4 | P26: 1 | Q26: 0 | R26: Parent.Quantity | T26: A - SUBSTRUCTURE | U26: A10 - Foundations | V26: A1010 - Standard | W26: A1012 - Column Foundations & Pile Caps | X26: 31 - EARTHWORK | Y26: 31 23 00 - Excavation and Fill | Z26: Machinery | AE26: 6
E27: 31.23.20.010.0 | G27: 30 23 23.14 2020 | H27: L.C.Y. | I27: 1.25 | J27: 0.012 | K27: 1.62 | L27: Backfill Excavation to Pad Footings | M27: CY | N27: CY/CY | O27: 1 | P27: 1 | Q27: 0 | R27: (A1012_001_CIP Pad Footing-ID.Net Top Surface Area*XX)+(A1012_001_CIP Pad Footing-ID.Edge Surface Area*1) | T27: A - SUBSTRUCTURE | U27: A10 - Foundations | V27: A1010 - Standard | W27: A1012 - Column Foundations & Pile Caps | X27: 31 - EARTHWORK | Y27: 31 23 20 - Excavation and Fill | AE27: 5
F28: LEXC001 | L28: Excavation Labor | M28: HR | N28: HR/CY | O28: 0.64 | P28: 1 | Q28: 0 | R28: Parent.Quantity | T28: A - SUBSTRUCTURE | U28: A10 - Foundations | V28: A1010 - Standard | W28: A1012 - Column Foundations & Pile Caps | X28: 31 - EARTHWORK | Y28: 31 23 20 - Excavation and Fill | Z28: Labor | AA28: LEXC | AE28: 6
F29: PEXC0101 | L29: JCB 3C | M29: HR | N29: HR/CY | O29: 0.32 | P29: 1 | Q29: 0 | R29: Parent.Quantity | T29: A - SUBSTRUCTURE | U29: A10 - Foundations | V29: A1010 - Standard | W29: A1012 - Column Foundations & Pile Caps | X29: 31 - EARTHWORK | Y29: 31 23 20 - Excavation and Fill | Z29: Machinery | AE29: 6
E30: 31.23.20.100.0 | G30: 33 23 23.24 0600 | H30: E.C.Y. | I30: 0.9 | J30: 0.04 | K30: 3.34 | L30: Fill compaction - Vibratory plate | M30: CY | N30: CY/CY | O30: 1 | P30: 1 | Q30: 0 | R30: (A1012_001_CIP Pad Footing-ID.Net Top Surface Area*XX)+(A1012_001_CIP Pad Footing-ID.Edge Surface Area*1) | T30: A - SUBSTRUCTURE | U30: A10 - Foundations | V30: A1010 - Standard | W30: A1012 - Column Foundations & Pile Caps | X30: 31 - EARTHWORK | Y30: 31 23 20 - Excavation and Fill | AE30: 5
F31: LEXC001 | L31: Excavation Labor | M31: HR | N31: HR/CY | O31: 0.026 | P31: 1 | Q31: 0 | R31: Parent.Quantity | T31: A - SUBSTRUCTURE | U31: A10 - Foundations | V31: A1010 - Standard | W31: A1012 - Column Foundations & Pile Caps | X31: 31 - EARTHWORK | Y31: 31 23 20 - Excavation and Fill | Z31: Labor | AA31: LEXC | AE31: 6
E32: 31.23.30.020.0 | G32: 31 23 23.20 0014 | H32: L.C.Y. | I32: 1.25 | J32: 0.03 | K32: 3.33 | L32: Remove Surplus Excavated Material | M32: CY | N32: CY/CY | O32: 1 | P32: 1.1 | Q32: 0 | R32: A1012_001_CIP Pad Footing-ID.Net Volume | T32: A - SUBSTRUCTURE | U32: A10 - Foundations | V32: A1010 - Standard | W32: A1012 - Column Foundations & Pile Caps | X32: 31 - EARTHWORK | Y32: 31 23 30 - Excavation and Fill | AE32: 5
F33: LEXC001 | L33: Excavation Labor | M33: HR | N33: HR/CY | O33: 0.07 | P33: 1 | Q33: 0 | R33: Parent.Quantity | T33: A - SUBSTRUCTURE | U33: A10 - Foundations | V33: A1010 - Standard | W33: A1012 - Column Foundations & Pile Caps | X33: 31 - EARTHWORK | Y33: 31 23 30 - Excavation and Fill | Z33: Labor | AA33: LEXC | AE33: 6
F34: PDIS0101 | L34: Haul Spoils off Site | M34: CY | N34: CY/CY | O34: 1 | P34: 1 | Q34: 0 | R34: Parent.Quantity | T34: A - SUBSTRUCTURE | U34: A10 - Foundations | V34: A1010 - Standard | W34: A1012 - Column Foundations & Pile Caps | X34: 31 - EARTHWORK | Y34: 31 23 30 - Excavation and Fill | Z34: Machinery | AE34: 6
E35: 03.62.00.010.0 | G35: 03 62 16.50 | H35: SF | I35: 5.27 | J35: 0.229 | K35: 28 | L35: Grout Base Plates | M35: EA | N35: EA/EA | O35: 1 | P35: 1 | Q35: 0 | R35: A1012_001_CIP Pad Footing-ID.Count | T35: A - SUBSTRUCTURE | U35: A10 - Foundations | V35: A1010 - Standard | W35: A1012 - Column Foundations & Pile Caps | X35: 03 - CONCRETE | Y35: 03 62 00 - Non-Shrink Grouting | AE35: 5
F36: LCON001 | L36: Concrete Pourer | M36: HR | N36: HR/EA | O36: 0.75 | P36: 1 | Q36: 0 | R36: Parent.Quantity | T36: A - SUBSTRUCTURE | U36: A10 - Foundations | V36: A1010 - Standard | W36: A1012 - Column Foundations & Pile Caps | X36: 03 - CONCRETE | Y36: 03 62 00 - Non-Shrink Grouting | Z36: Labor | AA36: LCON | AE36: 6
F37: M03.62.00.010 | L37: Base Plates | M37: EA | N37: EA/EA | O37: 1 | P37: 1 | Q37: 0 | R37: Parent.Quantity | T37: A - SUBSTRUCTURE | U37: A10 - Foundations | V37: A1010 - Standard | W37: A1012 - Column Foundations & Pile Caps | X37: 03 - CONCRETE | Y37: 03 62 00 - Non-Shrink Grouting | Z37: Material | AB37: M03 | AC37: M03 62 00 | AE37: 6
E38: 03.62.00.020.0 | G38: 03 15 19.10 0300 | H38: Set | I38: 1 | J38: 0.4 | K38: 55 | L38: Fix Anchor Bolts | M38: EA | N38: EA/EA | O38: 4 | P38: 1 | Q38: 0 | R38: A1012_001_CIP Pad Footing-ID.Count | T38: A - SUBSTRUCTURE | U38: A10 - Foundations | V38: A1010 - Standard | W38: A1012 - Column Foundations & Pile Caps | X38: 03 - CONCRETE | Y38: 03 62 00 - Non-Shrink Grouting | AE38: 5
F39: LCON001 | L39: Concrete Pourer | M39: HR | N39: HR/EA | O39: 0.33 | P39: 1 | Q39: 0 | R39: Parent.Quantity | T39: A - SUBSTRUCTURE | U39: A10 - Foundations | V39: A1010 - Standard | W39: A1012 - Column Foundations & Pile Caps | X39: 03 - CONCRETE | Y39: 03 62 00 - Non-Shrink Grouting | Z39: Labor | AA39: LCON | AE39: 6
F40: M03.62.00.020 | L40: Anchor Bolts | M40: EA | N40: EA/EA | O40: 1 | P40: 1 | Q40: 0 | R40: Parent.Quantity | T40: A - SUBSTRUCTURE | U40: A10 - Foundations | V40: A1010 - Standard | W40: A1012 - Column Foundations & Pile Caps | X40: 03 - CONCRETE | Y40: 03 62 00 - Non-Shrink Grouting | Z40: Material | AB40: M03 | AC40: M03 62 00 | AE40: 6
...

Sheet BDG_WBS
A1: Code, 1 | B1: Code, 2 | C1: Code, 3 | D1: Code, 4 | E1: Code, 5 | F1: Code, 6 | G1: Description | H1: Unit | I1: Units | J1: Consumption | K1: Waste Factor | L1: Unit Cost | M1: Source Qty | O1: Tag-Uniformat 1 | P1: Tag-Uniformat 2 | Q1: Tag-Uniformat 3 | R1: Tag-Uniformat 4 | S1: Tag-CSI 1 | T1: Tag-CSI 2 | U1: Tag-Cost Type | V1: Tag-Labor Resource | W1: Tag-CSI Resource 1 | X1: Tag-CSI Resource 2 | Z1: Node
A2: F | G2: SPECIAL CONSTRUCTION & DEMOLITION | H2: - | I2: - | J2: 1 | K2: 1 | L2: 0 | M2: 1 | O2: F - SPECIAL CONSTRUCTION & DEMOLITION | Z2: 1
B3: F20 | G3: Selective Building Demolition | H3: - | I3: - | J3: 1 | K3: 1 | L3: 0 | M3: 1 | O3: F - SPECIAL CONSTRUCTION & DEMOLITION | P3: F20 - Selective Building Demolition | Z3: 2
C4: F2010 | G4: Building Elements Demolition | H4: - | I4: - | J4: 1 | K4: 1 | L4: 0 | M4: 1 | O4: F - SPECIAL CONSTRUCTION & DEMOLITION | P4: F20 - Selective Building Demolition | Q4: F2010 - Building Elements Demolition | Z4: 3
C5: F2020 | G5: Hazardous Components Abatement | H5: - | I5: - | J5: 1 | K5: 1 | L5: 0 | M5: 1 | O5: F - SPECIAL CONSTRUCTION & DEMOLITION | P5: F20 - Selective Building Demolition | Q5: F2020 - Hazardous Components Abatement | Z5: 3
A6: G | G6: BUILDING SITEWORK | H6: - | I6: - | J6: 1 | K6: 1 | L6: 0 | M6: 1 | O6: G - BUILDING SITEWORK | Z6: 1
B7: G10 | G7: Site Preparation | H7: - | I7: - | J7: 1 | K7: 1 | L7: 0 | M7: 1 | O7: G - BUILDING SITEWORK | P7: G10 - Site Preparation | Z7: 2
C8: G1010 | G8: Site Clearing | H8: - | I8: - | J8: 1 | K8: 1 | L8: 0 | M8: 1 | O8: G - BUILDING SITEWORK | P8: G10 - Site Preparation | Q8: G1010 - Site Clearing | Z8: 3
C9: G1020 | G9: Site Demolition and Relocations | H9: - | I9: - | J9: 1 | K9: 1 | L9: 0 | M9: 1 | O9: G - BUILDING SITEWORK | P9: G10 - Site Preparation | Q9: G1020 - Site Demolition and Relocations | Z9: 3
C10: G1030 | G10: Site Earthwork | H10: - | I10: - | J10: 1 | K10: 1 | L10: 0 | M10: 1 | O10: G - BUILDING SITEWORK | P10: G10 - Site Preparation | Q10: G1030 - Site Earthwork | Z10: 3
D11: G1031.001 | G11: Cut and Fill | H11: CY | I11: CY/CY | J11: 1 | K11: 1 | L11: 0 | M11: G1031.001_Cut and Fill.Net Volume | O11: G - BUILDING SITEWORK | P11: G10 - Site Preparation | Q11: G1030 - Site Earthwork | R11: G1031 - Site Grading Excavation | Z11: 4
E12: 31.23.00.100.0 | G12: Mass Excavation to Reduce levels | H12: CY | I12: CY/CY | J12: 1 | K12: 1 | L12: 0 | M12: G1031.001_Cut and Fill.Net Volume | O12: G - BUILDING SITEWORK | P12: G10 - Site Preparation | Q12: G1030 - Site Earthwork | R12: G1031 - Site Grading Excavation | S12: 31 - EARTHWORK | T12: 31 23 00 - Excavation and Fill | Z12: 5
F13: LEXC001 | G13: Excavation Labor | H13: HR | I13: HR/CY | J13: 0.096 | K13: 1 | L13: 0 | M13: Parent.Quantity | O13: G - BUILDING SITEWORK | P13: G10 - Site Preparation | Q13: G1030 - Site Earthwork | R13: G1031 - Site Grading Excavation | S13: 31 - EARTHWORK | T13: 31 23 00 - Excavation and Fill | U13: Labor | V13: LEXC | Z13: 6
F14: PEXC0103 | G14: Excavator | H14: HR | I14: HR/CY | J14: 0.096 | K14: 1 | L14: 0 | M14: Parent.Quantity | O14: G - BUILDING SITEWORK | P14: G10 - Site Preparation | Q14: G1030 - Site Earthwork | R14: G1031 - Site Grading Excavation | S14: 31 - EARTHWORK | T14: 31 23 00 - Excavation and Fill | U14: Machinery | Z14: 6
E15: 31.23.20.100.0 | G15: Mass Fill to Make up levels | H15: CY | I15: CY/CY | J15: 1 | K15: 1 | L15: 0 | M15: G1031.001_Cut and Fill.Net Volume | O15: G - BUILDING SITEWORK | P15: G10 - Site Preparation | Q15: G1030 - Site Earthwork | R15: G1031 - Site Grading Excavation | S15: 31 - EARTHWORK | T15: 31 23 20 - Excavation and Fill | Z15: 5
F16: LEXC001 | G16: Excavation Labor | H16: HR | I16: HR/CY | J16: 0.026 | K16: 1 | L16: 0 | M16: Parent.Quantity | O16: G - BUILDING SITEWORK | P16: G10 - Site Preparation | Q16: G1030 - Site Earthwork | R16: G1031 - Site Grading Excavation | S16: 31 - EARTHWORK | T16: 31 23 20 - Excavation and Fill | U16: Labor | V16: LEXC | Z16: 6
F17: PEXC0103 | G17: Excavator | H17: HR | I17: HR/CY | J17: 0.026 | K17: 1 | L17: 0 | M17: Parent.Quantity | O17: G - BUILDING SITEWORK | P17: G10 - Site Preparation | Q17: G1030 - Site Earthwork | R17: G1031 - Site Grading Excavation | S17: 31 - EARTHWORK | T17: 31 23 20 - Excavation and Fill | U17: Machinery | Z17: 6
F18: M31.23.20.100 | G18: Imported Fill Material | H18: HR | I18: HR/CY | J18: 0.026 | K18: 1 | L18: 0 | M18: Parent.Quantity | O18: G - BUILDING SITEWORK | P18: G10 - Site Preparation | Q18: G1030 - Site Earthwork | R18: G1031 - Site Grading Excavation | S18: 31 - EARTHWORK | T18: 31 23 20 - Excavation and Fill | U18: Material | W18: M31 | X18: M31 23 20 | Z18: 6
E19: 31.23.30.100.0 | G19: Remove Surplus Excavated Material | H19: CY | I19: CY/CY | J19: 1 | K19: 1 | L19: 0 | M19: G1031.001_Cut and Fill.Net Volume | O19: G - BUILDING SITEWORK | P19: G10 - Site Preparation | Q19: G1030 - Site Earthwork | R19: G1031 - Site Grading Excavation | S19: 31 - EARTHWORK | T19: 31 23 30 - Excavation and Fill | Z19: 5
F20: LEXC001 | G20: Excavation Labor | H20: HR | I20: HR/CY | J20: 0.07 | K20: 1 | L20: 0 | M20: Parent.Quantity | O20: G - BUILDING SITEWORK | P20: G10 - Site Preparation | Q20: G1030 - Site Earthwork | R20: G1031 - Site Grading Excavation | S20: 31 - EARTHWORK | T20: 31 23 30 - Excavation and Fill | U20: Labor | V20: LEXC | Z20: 6
F21: PDIS0101 | G21: Haul Spoils off Site | H21: CY | I21: CY/CY | J21: 1 | K21: 1 | L21: 0 | M21: Parent.Quantity | O21: G - BUILDING SITEWORK | P21: G10 - Site Preparation | Q21: G1030 - Site Earthwork | R21: G1031 - Site Grading Excavation | S21: 31 - EARTHWORK | T21: 31 23 30 - Excavation and Fill | U21: Machinery | Z21: 6
C22: G1040 | G22: Hazardous Waste Remediation | H22: - | I22: - | J22: 1 | K22: 1 | L22: 0 | M22: 1 | O22: G - BUILDING SITEWORK | P22: G10 - Site Preparation | Q22: G1040 - Hazardous Waste Remediation | Z22: 3
B23: G20 | G23: Site Improvements | H23: - | J23: 1 | K23: 1 | L23: 0 | M23: 1 | O23: G - BUILDING SITEWORK | P23: G20 - Site Improvements | Z23: 2
C24: G2010 | G24: Roadways | H24: - | J24: 1 | K24: 1 | L24: 0 | M24: 1 | O24: G - BUILDING SITEWORK | P24: G20 - Site Improvements | Q24: G2010 - Roadways | Z24: 3
C25: G2020 | G25: Parking Lots | H25: - | J25: 1 | K25: 1 | L25: 0 | M25: 1 | O25: G - BUILDING SITEWORK | P25: G20 - Site Improvements | Q25: G2020 - Parking Lots | Z25: 3
C26: G2030 | G26: Pedestrian Paving | H26: - | J26: 1 | K26: 1 | L26: 0 | M26: 1 | O26: G - BUILDING SITEWORK | P26: G20 - Site Improvements | Q26: G2030 - Pedestrian Paving | Z26: 3
C27: G2040 | G27: Site Development | H27: - | J27: 1 | K27: 1 | L27: 0 | M27: 1 | O27: G - BUILDING SITEWORK | P27: G20 - Site Improvements | Q27: G2040 - Site Development | Z27: 3
C28: G2050 | G28: Landscaping | H28: - | J28: 1 | K28: 1 | L28: 0 | M28: 1 | O28: G - BUILDING SITEWORK | P28: G20 - Site Improvements | Q28: G2050 - Landscaping | Z28: 3
B29: G30 | G29: Site Mechanical Utilities | H29: - | I29: - | J29: 1 | K29: 1 | L29: 0 | M29: 1 | O29: G - BUILDING SITEWORK | P29: G30 - Site Mechanical Utilities | Z29: 2
C30: G3010 | G30: Water Supply | H30: - | I30: - | J30: 1 | K30: 1 | L30: 0 | M30: 1 | O30: G - BUILDING SITEWORK | P30: G30 - Site Mechanical Utilities | Q30: G3010 - Water Supply | Z30: 3
C31: G3020 | G31: Sanitary Sewer | H31: - | I31: - | J31: 1 | K31: 1 | L31: 0 | M31: 1 | O31: G - BUILDING SITEWORK | P31: G30 - Site Mechanical Utilities | Q31: G3020 - Sanitary Sewer | Z31: 3
C32: G3030 | G32: Storm Sewer | H32: - | I32: - | J32: 1 | K32: 1 | L32: 0 | M32: 1 | O32: G - BUILDING SITEWORK | P32: G30 - Site Mechanical Utilities | Q32: G3030 - Storm Sewer | Z32: 3
C33: G3040 | G33: Heating Distribution | H33: - | I33: - | J33: 1 | K33: 1 | L33: 0 | M33: 1 | O33: G - BUILDING SITEWORK | P33: G30 - Site Mechanical Utilities | Q33: G3040 - Heating Distribution | Z33: 3
C34: G3050 | G34: Cooling Distribution | H34: - | I34: - | J34: 1 | K34: 1 | L34: 0 | M34: 1 | O34: G - BUILDING SITEWORK | P34: G30 - Site Mechanical Utilities | Q34: G3050 - Cooling Distribution | Z34: 3
C35: G3060 | G35: Fuel Distribution | H35: - | I35: - | J35: 1 | K35: 1 | L35: 0 | M35: 1 | O35: G - BUILDING SITEWORK | P35: G30 - Site Mechanical Utilities | Q35: G3060 - Fuel Distribution | Z35: 3
C36: G3090 | G36: Other Site Mechanical Utilities | H36: - | I36: - | J36: 1 | K36: 1 | L36: 0 | M36: 1 | O36: G - BUILDING SITEWORK | P36: G30 - Site Mechanical Utilities | Q36: G3090 - Other Site Mechanical Utilities | Z36: 3
B37: G40 | G37: Site Electrical Utilities | H37: - | I37: - | J37: 1 | K37: 1 | L37: 0 | M37: 1 | O37: G - BUILDING SITEWORK | P37: G40 - Site Electrical Utilities | Z37: 2
C38: G4010 | G38: Electrical Distribution | H38: - | I38: - | J38: 1 | K38: 1 | L38: 0 | M38: 1 | O38: G - BUILDING SITEWORK | P38: G40 - Site Electrical Utilities | Q38: G4010 - Electrical Distribution | Z38: 3
C39: G4020 | G39: Site Lighting | H39: - | I39: - | J39: 1 | K39: 1 | L39: 0 | M39: 1 | O39: G - BUILDING SITEWORK | P39: G40 - Site Electrical Utilities | Q39: G4020 - Site Lighting | Z39: 3
C40: G4030 | G40: Site Communications & Security | H40: - | I40: - | J40: 1 | K40: 1 | L40: 0 | M40: 1 | O40: G - BUILDING SITEWORK | P40: G40 - Site Electrical Utilities | Q40: G4030 - Site Communications & Security | Z40: 3
...

Sheet Quantities
A1: Code | B1: Name | C1: Metric Unit | D1: Imperial Unit | E1: Obsolate flag
A2: Av_Height | B2: Av_Height | C2: M | D2: FT | E2: 0
A3: Base_Elevation | B3: Base_Elevation | C3: M | D3: FT | E3: 0
A4: Base_Height | B4: Base_Height | C4: M | D4: FT | E4: 0
A5: Base_Perimeter | B5: Base_Perimeter | C5: M | D5: FT | E5: 0
A6: Bottom_Area | B6: Bottom_Area | C6: M2 | D6: SF | E6: 0
A7: Bottom_Gross_Surface_Area | B7: Bottom_Gross_Surface_Area | C7: M2 | D7: SF | E7: 0
A8: Bottom_Net_Surface_Area | B8: Bottom_Net_Surface_Area | C8: M2 | D8: SF | E8: 0
A9: Calculated_Net_Floor_Surface_Area | B9: Calculated_Net_Floor_Surface_Area | C9: M2 | D9: SF | E9: 0
A10: Center_Line_Length | B10: Center_Line_Length | C10: M | D10: FT | E10: 0
A11: Center_Line_Gross_Area | B11: Center_Line_Gross_Area | C11: M2 | D11: SF | E11: 0
A12: Component_Net_Volume | B12: Component_Net_Volume | C12: M3 | D12: CY | E12: 0
... A178: weeks | B178: weeks | C178: WEEKS | D178: WEEKS | E178: 0

Sheet Lists
A1: = | B1: Beam | C1: Column | D1: Door | E1: Mesh | F1: MEP | G1: Object | H1: Roof | I1: Slab | J1: Stair | K1: Wall | L1: Window | M1: Zone | O1: Beam | P1: BeamP
A2: <> | B2: Bottom_Area | C2: Base_Elevation | D2: Base_Elevation | E2: Base_Elevation | F2: Base_Elevation | G2: Base_Elevation | H2: Bottom_Gross_Surface_Area | I2: Base_Elevation | J2: Base_Elevation | K2: Av_Height | L2: Base_Elevation | M2: Base_Elevation | O2: Column | P2: ColumnP
A3: <= | B3: Count | C3: Core_Depth | D3: Count | E3: Base_Height | F3: Count | G3: Bottom_Area | H3: Bottom_Net_Surface_Area | I3: Bottom_Gross_Surface_Area | J3: Count | K3: Base_Elevation | L3: Count | M3: Base_Perimeter | O3: Door | P3: DoorP
A4: > | B4: Formwork_Surface_Area | C4: Core_Gross_Top_Or_Bottom_Surface | D4: Frame_Depth | E4: Bottom_Area | F4: Foot_Print_Area | G4: Count | H4: Count | I4: Bottom_Net_Surface_Area | J4: Footprint_Area | K4: Bottom_Area | L4: Frame_Depth | M4: Calculated_Net_Floor_Surface_Area | O4: Mesh | P4: MeshP
A5: >= | B5: Height | C5: Core_Gross_Vertical_Surface_Area | D5: Gross_Surface_Area | E5: Count | F5: Height | G5: Height | H5: Edge_Count | I5: Component_Net_Volume[0] | J5: Formwork_Riser_Surface_Area | K5: Center_Line_Length | L5: Gross_Surface_Area | M5: Concave_Corner_Count | O5: MEP | P5: MEPP
A6: contains | B6: Hole_Count | C6: Core_Gross_Volume | D6: Head_Depth | E6: Edge_Count | F6: Length | G6: Length | H6: Edge_Gross_Surface_Area | I6: Component_Net_Volume[1] | J6: Formwork_Sides_Surface_Area | K6: Count | L6: Head_Depth | M6: Corner_Count | O6: Object | P6: ObjectP
A7: not contains | B7: Hole_Edge_Net_Surface_Area | C7: Core_Net_Bottom_Surface_Area | D7: Head_Height | E7: Edge_Net_Surface_Area | F7: Net_Surface_Area | G7: Net_Surface_Area | H7: Edge_Net_Surface_Area | I7: Component_Net_Volume[2] | J7: Height | K7: Door_Count | L7: Head_Height | M7: Count | O7: Roof | P7: RoofP
B8: Hole_Net_Surface_Area | C8: Core_Net_Top_Surface_Area | D8: Height | E8: Gross_Perimeter | F8: Net_Volume | G8: Net_Volume | H8: Gross_Surface_Area | I8: Component_Net_Volume[3] | J8: Horizontal_Bottom_Surface_Area | K8: Door_Surface_Area | L8: Height | M8: Edge_Gross_Vertical_Surface_Area | O8: Slab | P8: SlabP
A9: AND | B9: Length | C9: Core_Net_Vertical_Surface_Area | D9: Left_Jamb_Depth | E9: Gross_Surface_Area | F9: Number | G9: Width | H9: Hole_Count | I9: Component_Thickness[0] | J9: Horizontal_Finish_Surface_Area | K9: Empty_Opening_Count | L9: Left_Jamb_Depth | M9: Floor_Surface_Area_Reduction_Factor | O9: Stair | P9: StairP
A10: OR | B10: Net_Hole_Volume | C10: Core_Net_Volume | D10: Net_Perimeter | E10: Hole_Count | F10: Volume | H10: Hole_Perimeter | I10: Component_Thickness[1] | J10: Inclined_Surface_area | K10: Empty_Opening_Surface_Area | L10: Net_Surface_Area | M10: Gross_Surface_Area | O10: Wall | P10: WallP
B11: Net_Volume | C11: Core_Weight | D11: Net_Surface_Area | E11: Hole_Net_Surface_Area | F11: Weight | H11: Hole_Surface_Area | I11: Component_Thickness[2] | J11: Inner_Length | K11: End_Thickness | L11: Net_Volume | M11: Gross_Wall_Surface_Area | O11: Window | P11: WindowP
A12: 0 | B12: Opp_Ref_Side_Length | C12: Core_Width | D12: Net_Volume | E12: Hole_Perimeter | F12: Width | H12: Net_Surface_Area | I12: Component_Thickness[3] | J12: Length | K12: Foot_Print | L12: Opening_Net_Volume | M12: Height | O12: Zone | P12: ZoneP
A13: 1 | B13: Opp_Ref_Side_Net_Surface_Area | C13: Count | D13: Opening_Net_Volume | E13: Net_Volume | H13: Net_Volume | I13: Count | J13: Middle_Length | K13: Gross_Surface_Area | L13: Opening_Nominal_Volume | M13: Net_Edge_Perimeter
B14: Perimeter | C14: Gross_Volume | D14: Opening_Nominal_Volume | E14: Node_Count | H14: Node_Count | I14: Edge_Count | J14: Net_Surface_Area | K14: Gross_Volume | L14: Opp_Reveal_Side_Head_Height | M14: Net_Hole_Perimeter
B15: Ref_Line_Offset | C15: Height | D15: Opp_Reveal_Side_Head_Height | E15: Thickness | H15: Perimeter | I15: Edge_Gross_Surface_Area | J15: Net_Volume | K15: Height | L15: Opp_Reveal_Side_Net_Surface_Area | M15: Net_Perimeter
B16: Ref_Side_Length | C16: Net_Volume | D16: Opp_Reveal_Side_Net_Surface_Area | H16: Slope | I16: Edge_Net_Surface_Area | J16: Nosing_Length | K16: Length | L16: Opp_Reveal_Side_Nominal_Opening_Height | M16: Net_Surface_Area
B17: Ref_Side_Net_Surface_Area | C17: Perimeter | D17: Opp_Reveal_Side_Nominal_Opening_Height | H17: Thickness | I17: Formwork_Surface_Area | J17: Outer_Length | K17: Max_Height | L17: Opp_Reveal_Side_Nominal_Opening_Surface_Area | M17: Net_Volume
A18: CY | B18: Section_Area | C18: Section_Area | D18: Opp_Reveal_Side_Nominal_Opening_Surface_Area | I18: Gross_Perimeter | J18: Riser_Count | K18: Min_Height | L18: Opp_Reveal_Side_Nominal_Opening_Width | M18: Net_Wall_Perimeter
A19: DEG | B19: Sum_Ends_Net_Surface_Area | C19: Skin_Gross_Top_Or_Bottom_Surface_Area | D19: Opp_Reveal_Side_Nominal_Opening_Width | I19: Gross_Surface_Area | J19: Stair_Volume | K19: Net_Surface_Area | L19: Opp_Reveal_Side_Opening_Height | M19: Net_Wall_Surface_Area
A20: EA | B20: Top_Elevation | C20: Skin_Gross_Vertical_Surface_Area | D20: Opp_Reveal_Side_Opening_Height | I20: Hole_Count | J20: Vertical_Finish_Surface_Area | K20: Net_Volume | L20: Opp_Reveal_Side_Opening_Width | M20: Perimeter
A21: FT | B21: Top_Net_Surface_Area | C21: Skin_Gross_Volume | D21: Opp_Reveal_Side_Opening_Width | I21: Hole_Net_Surface_Area | J21: Width | K21: Opp_Ref_Side_Gross_Surface_Area | L21: Opp_Reveal_Side_Sill_Height | M21: Reduced_Calculated_Net_Floor_Surface_Area
A22: HR | B22: Total_Net_Surface_Area | C22: Skin_Net_Bottom_Surface_Area | D22: Opp_Reveal_Side_Sill_Height | I22: Hole_Perimeter | K22: Opp_Ref_Side_Length | L22: Perimeter | M22: Sub_Floor_Thickness
A23: KG | B23: Weight | C23: Skin_Net_Top_Surface_Area | D23: Perimeter | I23: Net_Surface_Area | K23: Opp_Ref_Side_Net_Hole_Surface_Area | L23: Position | M23: Subtracted_Column_Foot_Print_Area
A24: LB | B24: Width | C24: Skin_Net_Vertical_Surface_Area | D24: Position | I24: Net_Volume | K24: Opp_Ref_Side_Net_Surface_Area | L24: Reveal_Side_Head_Height | M24: Subtracted_Fill_Area
A25: LF | C25: Skin_Net_Volume | D25: Reveal_Side_Head_Height | I25: Node_Count | K25: Ref_Side_Length | L25: Reveal_Side_Nominal_Opening_Height | M25: Subtracted_Non_Usable_Area
A26: M | C26: Skin_Thickness | D26: Reveal_Side_Nominal_Opening_Height | I26: Perimeter | K26: Ref_Side_Net_Hole_Surface_Area | L26: Reveal_Side_Nominal_Opening_Surface_Area | M26: Subtracted_Wall_Foot_Print_Area
A27: M2 | C27: Skin_Weight | D27: Reveal_Side_Nominal_Opening_Surface_Area | I27: Thickness | K27: Section_Perimeter | L27: Reveal_Side_Nominal_Opening_Width | M27: Sum_Door_Surface_Area
A28: M3 | C28: Slant_Angle | D28: Reveal_Side_Nominal_Opening_Width | I28: Weight | K28: Slant_Angle | L28: Reveal_Side_Opening_Height | M28: Sum_Door_Width
A29: NR | D29: Reveal_Side_Opening_Height | I29: Width | K29: Start_Thickness | L29: Reveal_Side_Opening_Width | M29: Sum_Window_Surface_Area
A30: SF | D30: Reveal_Side_Opening_Width | K30: Sum_Door_Width | L30: Reveal_Side_Sill_Height | M30: Sum_Window_Width
A31: TONS | D31: Reveal_Side_Sill_Height | K31: Sum_Edge_Net_Surface_Area | L31: Right_Jamb_Depth | M31: Total_Subtracted_Area
A32: WEEKS | D32: Right_Jamb_Depth | K32: Sum_Gross_Vertical_Surface_Area | L32: Sill | M32: Wall_Inset_Back_Surface_Area
D33: Sill | K33: Sum_Net_Vertical_Surface_Area | L33: Sill_Depth | M33: Wall_Inset_Side_Surface_Area
D34: Sill_Depth | K34: Sum_Window_Width | L34: Sill_Height | M34: Wall_Inset_Top_Surface_Area
D35: Sill_Height | K35: Thickness | L35: Sub_Floor_Thickness
D36: Sub_Floor_Thickness | K36: Wall_Column_Count | L36: Thickness
D37: Thickness | K37: Weight | L37: Width
D38: Width | K38: Window_Count
K39: Window_Surface_Area
K42: WallP
...

Sheet Units
A1: Name | B1: SI factor (Metric\Imperial) | C1: Unit type | F1: A Units sheet was added to the excel book in the newest version of Dbtool. This sheet contains the units by their names, contains the si_factor and the unit type (neutral-0, metric-1, imperial-2). In this sheet user should define all units he will use in quantities sheet, because if the unit used in quantities, but not defined in units sheet error message will apeare, and the quantitie wont be imprted to the database.
A2: CY | B2: 1.3079506 | C2: 2
A3: DEG | B3: 0.01745329 | C3: 0
A4: EA | B4: 1 | C4: 0
A5: FT | B5: 3.2808399 | C5: 2
A6: KG | B6: 1 | C6: 1
A7: LB | B7: 0.45359237 | C7: 2
A8: LF | B8: 3.2808399 | C8: 2
A9: M | B9: 1 | C9: 1
A10: M2 | B10: 1 | C10: 1
A11: M3 | B11: 1 | C11: 1
A12: NR | B12: 1 | C12: 1
A13: SF | B13: 10.76391 | C13: 2
... A16: HR | B16: 1 | C16: 0
A19: CY | B19: 1.3079506
A20: FT | B20: 3.2808399
A21: LF | B21: 3.2808399
A22: SF | B22: 10.76391

Sheet Recipe classification
A1: Code | B1: Parent code | C1: Name
A2: A | C2: SUBSTRUCTURE
A3: A10 | B3: A | C3: Foundations
A4: A1010 | B4: A10 | C4: Standard
A5: A1011 | B5: A1010 | C5: Wall Foundations
A6: A1012 | B6: A1010 | C6: Column Foundations & Pile Caps
A7: A1013 | B7: A1010 | C7: Perimeter Drainage & Insulation
A8: A1020 | B8: A10 | C8: Special Foundations
A9: A1021 | B9: A1020 | C9: Pile Foundations
A10: A1022 | B10: A1020 | C10: Grade Beams
A11: A1023 | B11: A1020 | C11: Caissons
A12: A1024 | B12: A1020 | C12: Underpinning
A13: A1025 | B13: A1020 | C13: Dewatering
A14: A1026 | B14: A1020 | C14: Raft Foundations
... A32: A2024 | B32: A2020 | C32: Interior Skin
A33: B | C33: SHELL
A34: B10 | B34: B | C34: Superstructure
A35: B1010 | B35: B10 | C35: Floor Construction
A36: B1011 | B36: B1010 | C36: Suspended Basement Floors
A37: B1012 | B37: B1010 | C37: Upper Floors Construction
A38: B1013 | B38: B1010 | C38: Balcony Floors Construction
A39: B1014 | B39: B1010 | C39: Ramps
A40: B1015 | B40: B1010 | C40: Exterior Stairs and Fire Escapes
A41: B1016 | B41: B1010 | C41: Floor Raceway Systems
A42: B1019 | B42: B1010 | C42: Other Floor Construction
A43: B1020 | B43: B10 | C43: Roof Construction
A44: B1021 | B44: B1020 | C44: Flat Roof Construction
A45: B1022 | B45: B1020 | C45: Pitched Roof Construction
... A77: B3023 | B77: B3020 | C77: Gravity Roof Ventilators
A78: C | C78: INTERIORS
A79: C10 | B79: C | C79: Interior Construction
A80: C1010 | B80: C10 | C80: Partitions
A81: C1011 | B81: C1010 | C81: Fixed Partitions
A82: C1012 | B82: C1010 | C82: Demountable Partitions
A83: C1013 | B83: C1010 | C83: Retractable Partitions
A84: C1014 | B84: C1010 | C84: Site Built Toilet Partitions
A85: C1015 | B85: C1010 | C85: Site Built Compartments Cubicles
A86: C1016 | B86: C1010 | C86: Interior Balustrades and Screens
A87: C1017 | B87: C1010 | C87: Interior Windows & Storefronts
A88: C1020 | B88: C10 | C88: Interior Doors
...

Sheet Method classification
A1: Code | B1: Parent code | C1: Name
A2: CSI | C2: CSI MASTERFORMAT
A3: UNI | C3: UNIFORMAT 2 HIGH LEVEL PRICING/4D ITEMS
A4: 00 | B4: CSI | C4: PROCUREMENT AND CONTRACTING REQUIREMENTS
A5: 01 | B5: CSI | C5: GENERAL REQUIREMENTS
A6: 02 | B6: CSI | C6: EXISTING CONDITIONS
A7: 03 | B7: CSI | C7: CONCRETE
A8: 04 | B8: CSI | C8: MASONRY
A9: 05 | B9: CSI | C9: METALS
A10: 06 | B10: CSI | C10: WOODS, PLASTICS, COMPOSITES
A11: 07 | B11: CSI | C11: THERMAL & MOISTURE PROTECTION
A12: 08 | B12: CSI | C12: OPENINGS
A13: 09 | B13: CSI | C13: FINISHES
A14: 10 | B14: CSI | C14: SPECIALTIES
A15: 11 | B15: CSI | C15: EQUIPMENT
... A1520: Z30 | B1520: Z | C1520: Inflation Allowance

Sheet Resource classification
A1: Code | B1: Parent code | C1: Name | D1: Resource type
A2: LMSEO | C2: Detail Resources | D2: 3
A3: UNI | C3: Uniformat High Level MPS | D3: 3
A4: 1 | B4: LMSEO | C4: Labor | D4: 1
A5: 2 | B5: LMSEO | C5: Materials | D5: 2
A6: 3 | B6: LMSEO | C6: Subcontract | D6: 3
A7: 4 | B7: LMSEO | C7: Equipment | D7: 4
A8: 5 | B8: LMSEO | C8: Other | D8: 5
A9: 1-A | B9: 1 | C9: A | D9: 1
A10: 1-B | B10: 1 | C10: B | D10: 1
A11: 1-C | B11: 1 | C11: C | D11: 1
A12: 1-D | B12: 1 | C12: D | D12: 1
A13: 1-E | B13: 1 | C13: E | D13: 1
A14: 1-F | B14: 1 | C14: F | D14: 1
A15: 1-G | B15: 1 | C15: G | D15: 1
... A1162: 4-29 | B1162: 402 | C1162: Support | D1162: 4
A1163: 501 | B1163: 5 | C1163: Preliminary Items | D1163: 5
A1164: 502 | B1164: 5 | C1164: Fees | D1164: 5
A1165: 503 | B1165: 5 | C1165: General | D1165: 5
A1166: 504 | B1166: 5 | C1166: Temporary Works | D1166: 5
A1167: 505 | B1167: 5 | C1167: Contingency & OHP | D1167: 5
A1168: 5-01 | B1168: 501 | C1168: Permanent Staff | D1168: 5
A1169: 5-02 | B1169: 501 | C1169: Staff prior to start on site (enabling works) | D1169: 5
A1170: 5-03 | B1170: 501 | C1170: Agency staff | D1170: 5
A1171: 5-04 | B1171: 501 | C1171: Site Set-up | D1171: 5
A1172: 5-05 | B1172: 501 | C1172: Accomodation | D1172: 5
A1173: 5-06 | B1173: 501 | C1173: Safety | D1173: 5
A1174: 5-07 | B1174: 501 | C1174: Client office and equipment | D1174: 5
A1175: 5-08 | B1175: 501 | C1175: Relocation Costs | D1175: 5
A1176: 5-09 | B1176: 501 | C1176: HoardingHoarding/compound Set-up | D1176: 5
A1177: 5-10 | B1177: 501 | C1177: Sign Boards | D1177: 5
A1178: 5-11 | B1178: 501 | C1178: Temporary Electrics Distribution | D1178: 5
A1179: 5-12 | B1179: 501 | C1179: Compound temporary power | D1179: 5
... A1219: 5-52 | B1219: 503 | C1219: Contingency & OHP | D1219: 5
A1220: A | B1220: UNI | C1220: SUBSTRUCTURE | D1220: 3
A1221: A10 | B1221: A | C1221: Foundations | D1221: 3
A1222: A1010 | B1222: A10 | C1222: Standard | D1222: 3
A1223: A1011 | B1223: A1010 | C1223: Wall Foundations | D1223: 3
A1224: A1012 | B1224: A1010 | C1224: Column Foundations & Pile Caps | D1224: 3
A1225: A1013 | B1225: A1010 | C1225: Perimeter Drainage & Insulation | D1225: 3
...

Sheet Recipes
A1: Code | B1: Linkage code | C1: Name | D1: Classification | E1: Class | F1: Quantity data type | G1: Unit | H1: Memo | J1: Recipe Classification
A2: A1011.300.001 | B2: A1011.300.001 | C2: CIP Continuous Footing | D2: =LEFT(A2,5) -> A1011 | E2: Wall | F2: Length | G2: =VLOOKUP(F2,Quantities!$A$2:$D$221,4,FALSE) -> LF | J2: =VLOOKUP(D2,'Recipe classification'!$A$1:$C$5001,3,FALSE) -> Wall Foundations
A3: A1011.300.002 | B3: A1011.300.002 | C3: CIP Stem Wall | D3: =LEFT(A3,5) -> A1011 | E3: Wall | F3: Length | G3: =VLOOKUP(F3,Quantities!$A$2:$D$221,4,FALSE) -> LF | J3: =VLOOKUP(D3,'Recipe classification'!$A$1:$C$5001,3,FALSE) -> Wall Foundations
A4: A1012.300.001 | B4: A1012.300.001 | C4: CIP Pad Footing | D4: =LEFT(A4,5) -> A1012 | E4: Slab | F4: Net_Volume | G4: =VLOOKUP(F4,Quantities!$A$2:$D$221,4,FALSE) -> CY | J4: =VLOOKUP(D4,'Recipe classification'!$A$1:$C$5001,3,FALSE) -> Column Foundations & Pile Caps
A5: A1012.300.002 | B5: A1012.300.002 | C5: Precast Pad Footing | D5: =LEFT(A5,5) -> A1012 | E5: Slab | F5: Net_Volume | G5: =VLOOKUP(F5,Quantities!$A$2:$D$221,4,FALSE) -> CY | J5: =VLOOKUP(D5,'Recipe classification'!$A$1:$C$5001,3,FALSE) -> Column Foundations & Pile Caps
A6: A1012.300.003 | B6: A1012.300.003 | C6: Pile Cap | D6: =LEFT(A6,5) -> A1012 | E6: Slab | F6: Net_Volume | G6: =VLOOKUP(F6,Quantities!$A$2:$D$221,4,FALSE) -> CY | J6: =VLOOKUP(D6,'Recipe classification'!$A$1:$C$5001,3,FALSE) -> Column Foundations & Pile Caps
A7: A1012.300.004 | B7: A1012.300.004 | C7: CIP Pedestal | D7: =LEFT(A7,5) -> A1012 | E7: Slab | F7: Net_Volume | G7: =VLOOKUP(F7,Quantities!$A$2:$D$221,4,FALSE) -> CY | J7: =VLOOKUP(D7,'Recipe classification'!$A$1:$C$5001,3,FALSE) -> Column Foundations & Pile Caps
A8: A1013.300.001 | B8: A1013.300.001 | C8: Perimeter Drainage | D8: =LEFT(A8,5) -> A1013 | E8: Wall | F8: Length | G8: =VLOOKUP(F8,Quantities!$A$2:$D$221,4,FALSE) -> LF | J8: =VLOOKUP(D8,'Recipe classification'!$A$1:$C$5001,3,FALSE) -> Perimeter Drainage & Insulation
A9: A1021.300.001 | B9: A1021.300.001 | C9: CIP RC Pile | D9: =LEFT(A9,5) -> A1021 | E9: Column | F9: Count | G9: =VLOOKUP(F9,Quantities!$A$2:$D$221,4,FALSE) -> EA | J9: =VLOOKUP(D9,'Recipe classification'!$A$1:$C$5001,3,FALSE) -> Pile Foundations
A10: A1021.300.002 | B10: A1021.300.002 | C10: Precast RC Pile | D10: =LEFT(A10,5) -> A1021 | E10: Column | F10: Count | G10: =VLOOKUP(F10,Quantities!$A$2:$D$221,4,FALSE) -> EA | J10: =VLOOKUP(D10,'Recipe classification'!$A$1:$C$5001,3,FALSE) -> Pile Foundations
A11: A1021.300.003 | B11: A1021.300.003 | C11: Steel Pile | D11: =LEFT(A11,5) -> A1021 | E11: Column | F11: Count | G11: =VLOOKUP(F11,Quantities!$A$2:$D$221,4,FALSE) -> EA | J11: =VLOOKUP(D11,'Recipe classification'!$A$1:$C$5001,3,FALSE) -> Pile Foundations
A12: A1021.300.004 | B12: A1021.300.004 | C12: Timber Pile | D12: =LEFT(A12,5) -> A1021 | E12: Column | F12: Count | G12: =VLOOKUP(F12,Quantities!$A$2:$D$221,4,FALSE) -> EA | J12: =VLOOKUP(D12,'Recipe classification'!$A$1:$C$5001,3,FALSE) -> Pile Foundations
A13: A1021.300.005 | B13: A1021.300.005 | C13: Composite Pile | D13: =LEFT(A13,5) -> A1021 | E13: Column | F13: Count | G13: =VLOOKUP(F13,Quantities!$A$2:$D$221,4,FALSE) -> EA | J13: =VLOOKUP(D13,'Recipe classification'!$A$1:$C$5001,3,FALSE) -> Pile Foundations
... A415: B2011.300.020 | B415: B2011.300.020 | C415: Ext Plaster Stucco | D415: =LEFT(A415,5) -> B2011 | E415: Wall | F415: Net_Surface_Area | G415: =VLOOKUP(F415,Quantities!$A$2:$D$221,4,FALSE) -> SF | J415: =VLOOKUP(D415,'Recipe classification'!$A$1:$C$5001,3,FALSE) -> Exterior Wall Construction
A416: B2011.300.030 | B416: B2011.300.030 | C416: CMU/Brick Cavity Wall | D416: =LEFT(A416,5) -> B2011 | E416: Wall | F416: Net_Surface_Area | G416: =VLOOKUP(F416,Quantities!$A$2:$D$221,4,FALSE) -> SF | J416: =VLOOKUP(D416,'Recipe classification'!$A$1:$C$5000,3,FALSE) -> Exterior Wall Construction
A417: B2012.300.010 | B417: B2012.300.010 | C417: Parapet Metal Wall Panel | D417: =LEFT(A417,5) -> B2012 | E417: Wall | F417: Net_Surface_Area | G417: =VLOOKUP(F417,Quantities!$A$2:$D$221,4,FALSE) -> SF | J417: =VLOOKUP(D417,'Recipe classification'!$A$1:$C$5001,3,FALSE) -> Parapets
A418: B2012.300.020 | B418: B2012.300.020 | C418: Parapet Plaster Stucco | D418: =LEFT(A418,5) -> B2012 | E418: Wall | F418: Net_Surface_Area | G418: =VLOOKUP(F418,Quantities!$A$2:$D$221,4,FALSE) -> SF | J418: =VLOOKUP(D418,'Recipe classification'!$A$1:$C$5000,3,FALSE) -> Parapets
A419: B2012.300.035 | B419: B2012.300.035 | C419: Parapet CMU/Brick Cavity Wall | D419: =LEFT(A419,5) -> B2012 | E419: Wall | F419: Net_Surface_Area | G419: =VLOOKUP(F419,Quantities!$A$2:$D$221,4,FALSE) -> SF | J419: =VLOOKUP(D419,'Recipe classification'!$A$1:$C$5000,3,FALSE) -> Parapets
A420: B2013.300.011 | B420: B2013.300.011 | C420: Louver System, horiz blades | D420: =LEFT(A420,5) -> B2013 | E420: Wall | F420: Net_Surface_Area | G420: =VLOOKUP(F420,Quantities!$A$2:$D$221,4,FALSE) -> SF | J420: =VLOOKUP(D420,'Recipe classification'!$A$1:$C$5001,3,FALSE) -> Exterior Louvers, Screens, and Fencing
A421: B2016.300.010 | B421: B2016.300.010 | C421: MWP Canopy Soffit | D421: =LEFT(A421,5) -> B2016 | E421: Slab | F421: Net_Surface_Area | G421: =VLOOKUP(F421,Quantities!$A$2:$D$221,4,FALSE) -> SF | J421: =VLOOKUP(D421,'Recipe classification'!$A$1:$C$5001,3,FALSE) -> Exterior Soffits
A422: B2021.300.011 | B422: B2021.300.011 | C422: Ext Punched Windows, Stucco | D422: =LEFT(A422,5) -> B2021 | E422: Window | F422: Gross_Surface_Area | G422: =VLOOKUP(F422,Quantities!$A$2:$D$221,4,FALSE) -> SF | J422: =VLOOKUP(D422,'Recipe classification'!$A$1:$C$5001,3,FALSE) -> Windows
A423: B2022.300.010 | B423: B2022.300.010 | C423: Ext Glazing System, clear | D423: =LEFT(A423,5) -> B2022 | E423: Wall | F423: Net_Surface_Area | G423: =VLOOKUP(F423,Quantities!$A$2:$D$221,4,FALSE) -> SF | J423: =VLOOKUP(D423,'Recipe classification'!$A$1:$C$5001,3,FALSE) -> Curtain Walls
A424: B2022.300.011 | B424: B2022.300.011 | C424: Ext Glazing System, spandrel | D424: =LEFT(A424,5) -> B2022 | E424: Wall | F424: Net_Surface_Area | G424: =VLOOKUP(F424,Quantities!$A$2:$D$221,4,FALSE) -> SF | J424: =VLOOKUP(D424,'Recipe classification'!$A$1:$C$5001,3,FALSE) -> Curtain Walls
A425: B2031.300.010 | B425: B2031.300.010 | C425: Automatic Bi-parting Sliding Door | D425: =LEFT(A425,5) -> B2031 | E425: Door | F425: Count | G425: =VLOOKUP(F425,Quantities!$A$2:$D$221,4,FALSE) -> EA | J425: =VLOOKUP(D425,'Recipe classification'!$A$1:$C$5001,3,FALSE) -> Glazed Doors & Entrances
A426: B2031.300.020 | B426: B2031.300.020 | C426: Automatic Telescoping Sliding Door | D426: =LEFT(A426,5) -> B2031 | E426: Door | F426: Count | G426: =VLOOKUP(F426,Quantities!$A$2:$D$221,4,FALSE) -> EA | J426: =VLOOKUP(D426,'Recipe classification'!$A$1:$C$5001,3,FALSE) -> Glazed Doors & Entrances
A427: B2031.300.030 | B427: B2031.300.030 | C427: Double Storefront Door | D427: =LEFT(A427,5) -> B2031 | E427: Door | F427: Count | G427: =VLOOKUP(F427,Quantities!$A$2:$D$221,4,FALSE) -> EA | J427: =VLOOKUP(D427,'Recipe classification'!$A$1:$C$5001,3,FALSE) -> Glazed Doors & Entrances
A428: B2031.300.040 | B428: B2031.300.040 | C428: Emergency Dept Storefront Door | D428: =LEFT(A428,5) -> B2031 | E428: Door | F428: Count | G428: =VLOOKUP(F428,Quantities!$A$2:$D$221,4,FALSE) -> EA | J428: =VLOOKUP(D428,'Recipe classification'!$A$1:$C$5001,3,FALSE) -> Glazed Doors & Entrances
A429: B2032.300.010 | B429: B2032.300.010 | C429: Ext Metal Door, Single Unrated | D429: =LEFT(A429,5) -> B2032 | E429: Door | F429: Count | G429: =VLOOKUP(F429,Quantities!$A$2:$D$221,4,FALSE) -> EA | J429: =VLOOKUP(D429,'Recipe classification'!$A$1:$C$5001,3,FALSE) -> Solid Exterior Doors
A430: B2032.300.020 | B430: B2032.300.020 | C430: Ext Metal Door, Double Unrated | D430: =LEFT(A430,5) -> B2032 | E430: Door | F430: Count | G430: =VLOOKUP(F430,Quantities!$A$2:$D$221,4,FALSE) -> EA | J430: =VLOOKUP(D430,'Recipe classification'!$A$1:$C$5001,3,FALSE) -> Solid Exterior Doors
A431: B2032.300.021 | B431: B2032.300.021 | C431: Ext Metal Door, Double Fire Rated | D431: =LEFT(A431,5) -> B2032 | E431: Door | F431: Count | G431: =VLOOKUP(F431,Quantities!$A$2:$D$221,4,FALSE) -> EA | J431: =VLOOKUP(D431,'Recipe classification'!$A$1:$C$5001,3,FALSE) -> Solid Exterior Doors
... A3316: B1012.300.PIPE-B.037 | B3316: B1012.300.PIPE-B.037 | C3316: Pipe8XXS Steel Beam | D3316: =LEFT(A3316,5) -> B1012 | E3316: Beam | F3316: Length | G3316: =VLOOKUP(F3316,Quantities!$A$2:$D$221,4,FALSE) -> LF | J3316: =VLOOKUP(D3316,'Recipe classification'!$A$1:$C$5001,3,FALSE) -> Upper Floors Construction

Sheet Methods
A1: Code | B1: Linkage code | C1: Name | D1: Classification | E1: Unit | F1: Version | G1: Memo | H1: Schedule factor | J1: Method Classification
A2: 03.11.00.010 | B2: 03.11.00.010 | C2: Erect Forms to CIP Concrete - Continuous Footing | D2: 03 11 00 | E2: SF | H2: 1 | J2: =VLOOKUP(D2,'Method classification'!$A$1:$C$5000,3,FALSE) -> Concrete Forming
A3: 03.11.00.020 | B3: 03.11.00.020 | C3: Erect Forms to CIP Concrete - CIP Stem Wall | D3: 03 11 00 | E3: SF | H3: 1 | J3: =VLOOKUP(D3,'Method classification'!$A$1:$C$5000,3,FALSE) -> Concrete Forming
A4: 03.11.00.040 | B4: 03.11.00.040 | C4: Erect Forms to CIP Concrete - CIP Pad Footing | D4: 03 11 00 | E4: SF | H4: 1 | J4: =VLOOKUP(D4,'Method classification'!$A$1:$C$5000,3,FALSE) -> Concrete Forming
A5: 03.11.00.060 | B5: 03.11.00.060 | C5: Erect Forms to CIP Concrete - Pile Cap | D5: 03 11 00 | E5: SF | H5: 1 | J5: =VLOOKUP(D5,'Method classification'!$A$1:$C$5000,3,FALSE) -> Concrete Forming
A6: 03.11.00.070 | B6: 03.11.00.070 | C6: Erect Forms to CIP Concrete - CIP Pedestal | D6: 03 11 00 | E6: SF | H6: 1 | J6: =VLOOKUP(D6,'Method classification'!$A$1:$C$5000,3,FALSE) -> Concrete Forming
A7: 03.11.00.090 | B7: 03.11.00.090 | C7: Erect Forms to CIP Concrete - Crane Foundation Pier | D7: 03 11 00 | E7: SF | H7: 1 | J7: =VLOOKUP(D7,'Method classification'!$A$1:$C$5000,3,FALSE) -> Concrete Forming
A8: 03.11.00.100 | B8: 03.11.00.100 | C8: Erect Forms to CIP Concrete - Tie Beam | D8: 03 11 00 | E8: SF | H8: 1 | J8: =VLOOKUP(D8,'Method classification'!$A$1:$C$5000,3,FALSE) -> Concrete Forming
A9: 03.11.00.110 | B9: 03.11.00.110 | C9: Erect Forms to CIP Concrete - Grade Beam | D9: 03 11 00 | E9: SF | H9: 1 | J9: =VLOOKUP(D9,'Method classification'!$A$1:$C$5000,3,FALSE) -> Concrete Forming
A10: 03.11.00.120 | B10: 03.11.00.120 | C10: Erect Forms to CIP Concrete - Capping Beam | D10: 03 11 00 | E10: SF | H10: 1 | J10: =VLOOKUP(D10,'Method classification'!$A$1:$C$5000,3,FALSE) -> Concrete Forming
A11: 03.11.00.130 | B11: 03.11.00.130 | C11: Erect Forms to CIP Concrete - Underpinning Wall | D11: 03 11 00 | E11: SF | H11: 1 | J11: =VLOOKUP(D11,'Method classification'!$A$1:$C$5000,3,FALSE) -> Concrete Forming
A12: 31.46.00.140 | B12: 31.46.00.140 | C12: Erect Forms to CIP Concrete - Needle Beams | D12: 31 46 00 | E12: SF | H12: 1 | J12: =VLOOKUP(D12,'Method classification'!$A$1:$C$5000,3,FALSE) -> Needle Beams
A13: 03.11.00.150 | B13: 03.11.00.150 | C13: Erect Forms to CIP Concrete - Mat-slab Foundation | D13: 03 11 00 | E13: SF | H13: 1 | J13: =VLOOKUP(D13,'Method classification'!$A$1:$C$5000,3,FALSE) -> Concrete Forming
... A6363: 05.12.65.PIPE.037bc | B6363: 05.12.65.PIPE.037bc | C6363: Erect Structural Steel Beam (Count) type Pipe8XXS | D6363: 05 12 00 | E6363: EA | H6363: 1 | J6363: =VLOOKUP(D6363,'Method classification'!$A$1:$C$5000,3,FALSE) -> Structural Steel Framing

Sheet Resources
A1: Code | B1: Linkage code | C1: Name | D1: Classification | E1: Type | F1: Unit | G1: Gross price | H1: Contract | I1: Source | J1: Supplier | K1: Supplier ID | L1: Responsible for the price | M1: Memo | O1: Resource Classification
A2: LROO005 | B2: LROO005 | C2: Asphalt Paver (Journeyman) | D2: 1-A | E2: Labor | F2: HR | G2: 0 | O2: =VLOOKUP(D2,'Resource classification'!$A$1:$D$4992,3,FALSE) -> A
A3: LROO006 | B3: LROO006 | C3: Asphalt Paver's Apprentice | D3: 1-A | E3: Labor | F3: HR | G3: 0 | O3: =VLOOKUP(D3,'Resource classification'!$A$1:$D$4992,3,FALSE) -> A
A4: LBRI001 | B4: LBRI001 | C4: Bricklayer | D4: 1-B | E4: Labor | F4: HR | G4: 0 | O4: =VLOOKUP(D4,'Resource classification'!$A$1:$D$4992,3,FALSE) -> B
A5: LBRI002 | B5: LBRI002 | C5: Bricklayer's Laborer | D5: 1-B | E5: Labor | F5: HR | G5: 0 | O5: =VLOOKUP(D5,'Resource classification'!$A$1:$D$4992,3,FALSE) -> B
A6: LBRI003 | B6: LBRI003 | C6: Bricklaying gang (2+1) | D6: 1-B | E6: Labor | F6: HR | G6: 0 | O6: =VLOOKUP(D6,'Resource classification'!$A$1:$D$4992,3,FALSE) -> B
A7: LCAR001 | B7: LCAR001 | C7: Finish Carpenter | D7: 1-C | E7: Labor | F7: HR | G7: 0 | O7: =VLOOKUP(D7,'Resource classification'!$A$1:$D$4992,3,FALSE) -> C
A8: LCAR002 | B8: LCAR002 | C8: Finish Carpenter's Laborer | D8: 1-C | E8: Labor | F8: HR | G8: 0 | O8: =VLOOKUP(D8,'Resource classification'!$A$1:$D$4992,3,FALSE) -> C
A9: LCON001 | B9: LCON001 | C9: Concrete Pourer | D9: 1-C | E9: Labor | F9: HR | G9: 0 | O9: =VLOOKUP(D9,'Resource classification'!$A$1:$D$4992,3,FALSE) -> C
A10: LCON002 | B10: LCON002 | C10: Cement Finisher | D10: 1-C | E10: Labor | F10: HR | G10: 0 | O10: =VLOOKUP(D10,'Resource classification'!$A$1:$D$4992,3,FALSE) -> C
A11: LCON003 | B11: LCON003 | C11: Formwork Carpenter | D11: 1-C | E11: Labor | F11: HR | G11: 0 | O11: =VLOOKUP(D11,'Resource classification'!$A$1:$D$4992,3,FALSE) -> C
A12: LCON004 | B12: LCON004 | C12: Rodman | D12: 1-C | E12: Labor | F12: HR | G12: 0 | O12: =VLOOKUP(D12,'Resource classification'!$A$1:$D$4992,3,FALSE) -> C
A13: LCON005 | B13: LCON005 | C13: Precast Concrete Labor | D13: 1-C | E13: Labor | F13: HR | G13: 0 | O13: =VLOOKUP(D13,'Resource classification'!$A$1:$D$4992,3,FALSE) -> C
... A2657: 05.12.65.PIPE.037 | B2657: 05.12.65.PIPE.037 | C2657: Structural Steel Section type Pipe8XXS | D2657: 05 12 00 | E2657: Materials | F2657: TON | G2657: 0 | O2657: =VLOOKUP(D2657,'Resource classification'!$A$1:$D$4992,3,FALSE) -> Structural Steel Framing
